Workbook

Sheet Panduan
B2: Database Buyer Manggis Segar: China & Timur Tengah
B3: Disusun 27 Sep 2026 dari sumber publik. Setiap baris punya link sumber. Verifikasi kontak sebelum mengirim penawaran.
B5: CARA PAKAI
B6: 1. Database Buyer | C6: Daftar buyer. Isi kolom kuning (PIC, Email, Telepon, Status, Follow-up, Catatan) setelah Anda verifikasi dari website buyer.
B7: 2. Penawaran | C7: Catat setiap penawaran harga. Isi kolom kuning; nama, negara, dan nilai terisi otomatis dari rumus.
B8: 3. Ringkasan | C8: Rekap otomatis jumlah buyer & nilai penawaran per negara. Jangan diketik manual.
B9: 4. Syarat Ekspor | C9: Checklist dokumen/regulasi per pasar tujuan, lengkap dengan sumber.
B11: KODE WARNA
B12: Sel kuning | C12: Input Anda (boleh diketik/diubah)
B13: Teks biru | C13: Angka asumsi yang diinput manual (mis. kurs)
B14: Teks hitam | C14: Rumus: jangan ditimpa
B16: PRIORITAS (penilaian awal)
B17: A | C17: Terbukti impor/menjual manggis (data kiriman, katalog, atau artikel)
B18: B | C18: Importir buah tropis/eksotis, sourcing dari Asia: kandidat kuat
B19: C | C19: Importir/ritel umum atau informasi terbatas: prospek sekunder
B21: PENGATURAN
B22: Kurs USD → IDR | C22: 16500
B24: CATATAN PENTING
B25: Kontak | C25: Email/telepon/PIC sengaja dikosongkan. Data kontak tidak dikarang; ambil langsung dari halaman 'Contact' di website buyer atau direktori resmi.
B26: Data kiriman | C26: Pangsa kiriman (Volza/NBD/ImportGenius) diambil dari ringkasan hasil pencarian; cek ulang sebelum dikutip.
B27: Musim | C27: Panen raya manggis Indonesia Okt–Mar. Hubungi buyer Timur Tengah Nov–Des 2026 untuk Ramadan 2027; buyer China untuk Imlek (Feb 2027).

Sheet Database Buyer
A1: DATABASE BUYER MANGGIS SEGAR
A2: ID | B2: Perusahaan | C2: Wilayah | D2: Negara | E2: Kota | F2: Tipe | G2: Prioritas | H2: Produk / Fokus | I2: Website | J2: PIC | K2: Email | L2: Telepon | M2: Alamat | N2: Status | O2: Follow-up Berikutnya | P2: Relevansi (hasil riset) | Q2: Sumber Verifikasi | R2: Catatan Anda
A3: B001 | B3: Beijing Junyao International | C3: China & HK | D3: China | E3: Beijing | F3: Importir | G3: A | H3: Manggis segar (Indonesia, Thailand) | N3: Baru | P3: ±31% kiriman impor manggis China (Volza); pemasok: PT Bumi Indo Nusantara Abadi | Q3: https://www.volza.com/p/mangosteen-fruit/buyers/buyers-in-china/
A4: B002 | B4: Shanghai Holdfresh Trading Co., Ltd. | C4: China & HK | D4: China | E4: Shanghai | F4: Importir | G4: A | H4: Buah tropis termasuk manggis | N4: Baru | P4: ±20% kiriman impor manggis China (Volza); importir manggis Indonesia | Q4: https://www.importgenius.com/importers/shanghai-holdfresh-trading-co-ltd
A5: B003 | B5: Chuannongjing (Hainan) International Trade Co., Ltd. | C5: China & HK | D5: China | E5: Hainan | F5: Importir | G5: A | H5: Produk segar global, manggis | I5: https://www.sclanghao.com/en/zhanluebuju/chuannongjing-hainan-guojimaoyiyouxiangongsi/ | N5: Baru | P5: ±17% kiriman manggis China (Volza); impor manggis Indonesia akhir 2024; anak usaha BUMD Sichuan | Q5: https://www.sclanghao.com/en/zhanluebuju/chuannongjing-hainan-guojimaoyiyouxiangongsi/
A6: B004 | B6: Beijing Junhui International Trading Co., Ltd. | C6: China & HK | D6: China | E6: Beijing | F6: Importir | G6: A | H6: Manggis dari Indonesia | N6: Baru | P6: Pembeli manggis Indonesia terbesar akhir 2024 (±USD 2,77 jt, NBD) | Q6: https://en.nbd.ltd/news/d/668bd591679ff7d42846ca3410eb591e
A7: B005 | B7: Shanghai Sunshine Agriculture Technology Co., Ltd. | C7: China & HK | D7: China | E7: Shanghai | F7: Importir | G7: A | H7: Manggis dari Indonesia | N7: Baru | P7: Pembeli manggis Indonesia (±USD 1,05 jt, akhir 2024, NBD) | Q7: https://en.nbd.ltd/news/d/668bd591679ff7d42846ca3410eb591e
A8: B006 | B8: Guangzhou Zhanhui Trade Co., Ltd. | C8: China & HK | D8: China | E8: Guangzhou | F8: Importir | G8: A | H8: Durian, lengkeng, manggis Thailand; buah naga Vietnam | M8: Pasar Buah Jiangnan, Guangzhou | N8: Baru | P8: Berbasis di Pasar Jiangnan; impor manggis Thailand | Q8: https://bbs.fobshanghai.com/company/1602f3ks4138ml6.html
A9: B007 | B9: Guangzhou Wen Wu He Tai Trading Co., Ltd. | C9: China & HK | D9: China | E9: Guangzhou | F9: Importir | G9: A | H9: Buah Asia Tenggara termasuk manggis | I9: http://en.gxmfruit.com | N9: Baru | P9: Fokus impor buah Asia Tenggara, pernah impor manggis | Q9: http://en.gxmfruit.com/About.aspx?ClassID=45
A10: B008 | B10: Shanghai Binyue Trade Co., Ltd. | C10: China & HK | D10: China | E10: Shanghai | F10: Wholesaler | G10: A | H10: Manggis Thailand (merek Limei) | M10: Pasar Buah Huizhan, Shanghai | N10: Baru | P10: Pedagang manggis di hub distribusi China Timur | Q10: https://www.producereport.com/article/thailand-enjoys-lions-share-chinas-mangosteen-market
A11: B009 | B11: Goodfarmer (Jianong Food Holding Group) | C11: China & HK | D11: China | E11: Shanghai | F11: Importir | G11: A | H11: Durian, lengkeng, manggis, pisang, nanas | I11: https://www.goodfarmer.com/en/about.html | N11: Baru | P11: Berdiri 2002; 30+ pusat distribusi; fokus buah tropis | Q11: https://www.goodfarmer.com/en/about.html
A12: B010 | B12: Joy Wing Mau Fruit Technologies Corp. | C12: China & HK | D12: China | E12: Shenzhen | F12: Distributor | G12: B | H12: Buah impor, durian Thailand; distribusi nasional | I12: https://www.joywingmau.com/en | N12: Baru | P12: Distributor buah impor terbesar di China; peserta Asia Fruit Logistica | Q12: https://www.freshfruitportal.com/news/2025/09/08/joy-wing-mau-group-asia-fruit-logistica/
A13: B011 | B13: Pagoda (Shenzhen Pagoda Industrial / Baiguoyuan) | C13: China & HK | D13: China | E13: Shenzhen | F13: Retail/Supermarket | G13: B | H13: Rantai ritel buah; sourcing langsung luar negeri | N13: Baru | P13: Ritel buah terbesar China; ekspansi ke Indonesia 2024 | Q13: https://www.prnewswire.com/news-releases/pagoda-makes-its-mark-at-asia-fruit-logistica-2024-launching-overseas-expansion-starting-with-indonesia-302238124.html
A14: B012 | B14: Xianfeng Fruit Co., Ltd. | C14: China & HK | D14: China | F14: Importir | G14: B | H14: Impor global termasuk durian Thailand; punya jaringan toko | N14: Baru | P14: Peserta Asia Fruit Logistica | Q14: https://www.freshplaza.com/north-america/photos/album/9463/asia-fruit-logistica-2019/
A15: B013 | B15: Huasheng International Trade (Guangzhou) Co., Ltd. | C15: China & HK | D15: China | E15: Guangzhou | F15: Wholesaler | G15: C | H15: Buah impor (ceri, anggur, blueberry, kiwi) | N15: Baru | P15: 25+ tahun di pasar Guangzhou; buah tropis bukan lini utama | Q15: https://www.cnverify.com/company/Huasheng-International-Trade-Guangzhou-Co-Ltd
A16: B014 | B16: Chongqing Hongjiu Fruit Co., Ltd. | C16: China & HK | D16: China | E16: Chongqing | F16: Distributor | G16: C | H16: Durian, manggis, lengkeng Thailand | N16: Baru | P16: Pernah impor manggis. PERHATIAN: delisting dari HKEX 2024 (cek kondisi keuangan, wajib LC/advance) | Q16: https://www.fruitnet.com/asiafruit/hongjiu-fruit-delisted-from-hong-kong-stock-exchange/270204.article
A17: B015 | B17: Sino Alliance Trading (Hong Kong) Limited | C17: China & HK | D17: Hong Kong | E17: Yau Ma Tei, Kowloon | F17: Importir | G17: A | H17: Buah segar dari 30+ negara | I17: https://www.sino-alliance.com/en/ | M17: Pasar Buah Yau Ma Tei | N17: Baru | P17: Salah satu importir buah terbesar HK; suplai Greater China. Kontak: /en/contact-us/ | Q17: https://www.sino-alliance.com/en/
A18: B016 | B18: CMC Fruit Company Limited | C18: China & HK | D18: Hong Kong | E18: Hong Kong | F18: Importir | G18: A | H18: Durian, lengkeng, pomelo, longkong Thailand | I18: https://cmcfruit.com/ | N18: Baru | P18: Impor buah tropis via udara setiap hari; 50–60 kontainer/bulan saat puncak | Q18: https://cmcfruit.com/
A19: B017 | B19: Chun Sing Fresh Fruit Trading Limited | C19: China & HK | D19: Hong Kong | E19: Yau Ma Tei, Kowloon | F19: Importir | G19: B | H19: Impor buah & sayur; grosir dan ritel | I19: https://www.csfruit.com.hk/ | M19: Pasar Buah Yau Ma Tei | N19: Baru | P19: Kontak ada di https://www.csfruit.com.hk/contact | Q19: https://www.csfruit.com.hk/about
A20: B018 | B20: Bailey Fresh Fruits Co., Ltd. (Prosperity Fresh Fruits Trading) | C20: China & HK | D20: Hong Kong | E20: Yau Ma Tei, Kowloon | F20: Importir | G20: B | H20: Durian dan buah tropis | N20: Baru | P20: ±13% kiriman impor durian HK (Volza) | Q20: https://panjiva.com/Bailey-Fresh-Fruits-Co-Ltd-T-A-Prosperity-Fresh-Fruits-Trading-Co/149746110
A21: B019 | B21: Wing Kee Produce Limited | C21: China & HK | D21: Hong Kong | E21: Kowloon Bay | F21: Importir | G21: B | H21: Buah & sayur termasuk tropis | I21: https://www.wingkee.com/ | N21: Baru | P21: Cold storage 50.000 sq ft; anak usaha di China. Kontak: /contact-us/ | Q21: https://www.wingkee.com/about-us/
A22: B020 | B22: Wah Kee Fresh Fruit & Vegetable Ltd | C22: China & HK | D22: Hong Kong | E22: Hong Kong | F22: Wholesaler | G22: C | H22: Buah & sayur segar | N22: Baru | P22: Terdaftar di direktori HKTDC; lini tropis belum terkonfirmasi | Q22: https://sourcing.hktdc.com/en/Supplier-Store-Directory/Wah-Kee-Fresh-Fruit-Vegetable-Ltd/1X09P9CX
A23: B021 | B23: Anusaya Fresh (Anusuya Fresh Fruits & Vegetables LLC) | C23: Timur Tengah | D23: UAE | E23: Dubai (Al Aweer) | F23: Importir | G23: A | H23: Apel, jeruk, anggur + eksotis: manggis, rambutan, buah naga | I23: http://www.anusayafresh.com | M23: Area Al Aweer Central Market, Dubai | N23: Baru | P23: Secara eksplisit impor manggis & rambutan; ada cabang Doha, Qatar | Q23: http://www.anusayafresh.com/aboutuae.html
A24: B022 | B24: Fresh Leaf UAE | C24: Timur Tengah | D24: UAE | E24: Dubai | F24: Distributor | G24: A | H24: Kategori buah eksotis termasuk 'Mangosteen Indonesia' | I24: https://freshleafuae.com | N24: Baru | P24: Sudah menjual manggis Indonesia: sangat cocok | Q24: https://freshleafuae.com/mangosteen-indonesia/
A25: B023 | B25: Euto Foods Trading | C25: Timur Tengah | D25: UAE | E25: Dubai | F25: Importir | G25: A | H25: Importir buah grosir; tropis termasuk manggis | I25: https://eutofoods.com | N25: Baru | P25: Menyebut sourcing manggis dari Asia | Q25: https://eutofoods.com/fruits-importer-in-uae/
A26: B024 | B26: Al Yusra Foodstuff Trading LLC | C26: Timur Tengah | D26: UAE | E26: Dubai | F26: Importir | G26: A | H26: Importir, distributor, commission agent buah & sayur; lini eksotis | I26: https://www.alyusrafoodstuff.com | N26: Baru | P26: Sumber dari Thailand, Malaysia, Indonesia | Q26: https://www.alyusrafoodstuff.com/other-fruits-importer.php
A27: B025 | B27: Source International | C27: Timur Tengah | D27: UAE | E27: Dubai | F27: Importir | G27: A | H27: Importir/distributor buah eksotis B2B | I27: https://sourceinternational.ae | N27: Baru | P27: Spesialis buah eksotis | Q27: https://sourceinternational.ae/exotic-fruit-importer-uae/
A28: B026 | B28: Barakat Vegetables & Fruits Co. LLC | C28: Timur Tengah | D28: UAE | E28: Dubai (Al Aweer) | F28: Distributor | G28: B | H28: Importir/distributor besar (53+ negara asal); HoReCa, ritel | I28: https://barakatfresh.ae | N28: Baru | P28: Peserta Gulfood 2026; ±350 truk reefer | Q28: https://www.gulfood.com/exhibitors/barakat-vegetables-fruit-company-llc-1
A29: B027 | B29: Fresh Avenue Foodstuff Trading LLC | C29: Timur Tengah | D29: UAE | E29: Dubai (Al Aweer) | F29: Wholesaler | G29: B | H29: Grosir buah & sayur, termasuk rambutan | I29: https://www.freshavenuefoodstufftradingllc.com | M29: Al Aweer Central Fruit & Vegetable Market | N29: Baru | P29: Sudah menangani buah eksotis Asia Tenggara | Q29: https://www.freshavenuefoodstufftradingllc.com/
A30: B028 | B30: MPF Foodstuff Trading (Meridian PF) | C30: Timur Tengah | D30: UAE | E30: Dubai | F30: Distributor | G30: B | H30: Buah musiman & eksotis | I30: https://meridianpf.com | N30: Baru | P30: Re-ekspor ke seluruh Timur Tengah | Q30: https://meridianpf.com/exporter-of-premium-seasonal-fruits-dubai/
A31: B029 | B31: AJMEER General Trading LLC | C31: Timur Tengah | D31: UAE | E31: Dubai (Al Aweer) | F31: Importir | G31: B | H31: Impor buah & sayur dari Asia, Eropa, Afrika; suplai hotel & ritel | I31: https://ajmeer.ae | M31: Dubai Al-Aweer Central Fruits & Vegetables Market | N31: Baru | P31: Sourcing Asia + distribusi HoReCa | Q31: https://ajmeer.ae/
A32: B030 | B32: Shabab Al Aweer Foodstuff Trading L.L.C. | C32: Timur Tengah | D32: UAE | E32: Dubai (Al Aweer) | F32: Importir | G32: B | H32: Impor/ekspor dan suplai buah & sayur | I32: https://shababalaweer.ae | M32: Shop 23, Block 6, Fruits & Vegetables Market, Al Aweer (cek ulang) | N32: Baru | P32: Trader impor di Al Aweer | Q32: https://shababalaweer.ae/
A33: B031 | B33: Kibsons | C33: Timur Tengah | D33: UAE | E33: Dubai (Al Aweer) | F33: E-commerce | G33: B | H33: Grocery online dengan kategori buah eksotis | I33: https://www.kibsons.com | M33: Shop 59, Bldg 2, Fruit & Vegetable Market, Aweer (cek ulang) | N33: Baru | P33: Importir sekaligus ritel online | Q33: https://www.kibsons.com/en/fruits/exotics
A34: B032 | B34: Al Maya Group (Al Maya Supermarkets) | C34: Timur Tengah | D34: UAE | E34: Dubai | F34: Retail/Supermarket | G34: C | H34: Rantai supermarket (±40 gerai UAE) | N34: Baru | P34: Tuan rumah Thai Fruits Festival 2026 (buah tropis Asia) | Q34: https://gulfnews.com/amp/story/business/corporate-news/thailand-expands-thai-fruits-food-festival-2026-campaign-through-al-maya-supermarkets-in-the-uae-1.500544329
A35: B033 | B35: Sharbatly Fruit | C35: Timur Tengah | D35: Saudi Arabia | E35: Jeddah | F35: Importir | G35: B | H35: Importir/distributor produk segar premium sejak 1930-an | I35: https://sharbatlyfruit.com | N35: Baru | P35: Salah satu rumah buah terbesar di KSA | Q35: https://sharbatlyfruit.com/
A36: B034 | B36: Shrayan Al Jazeera Fruits & Vegetables Trading | C36: Timur Tengah | D36: Saudi Arabia | E36: Jeddah | F36: Importir | G36: B | H36: Impor/ekspor buah & sayur sejak 2009 | I36: https://shrayanaljazeera.com | M36: Panorama Centre, office-5, Umm Al Qura St, Safa, Jeddah (cek ulang) | N36: Baru | P36: Mengklaim importir buah & sayur terbesar di KSA | Q36: https://shrayanaljazeera.com/
A37: B035 | B37: AFDAN Company for Fruits and Vegetables Trading | C37: Timur Tengah | D37: Saudi Arabia | E37: Riyadh | F37: Importir | G37: B | H37: Pengadaan/impor global buah & sayur | I37: https://www.afdan.sa/en/ | N37: Baru | P37: Importir berbasis Riyadh | Q37: https://www.afdan.sa/en/
A38: B036 | B38: BlissBerrys | C38: Timur Tengah | D38: Saudi Arabia | E38: Riyadh/Jeddah/Dammam | F38: Distributor | G38: B | H38: Alpukat, mangga, nanas, beri, jeruk ke supermarket & HoReCa | I38: https://blissberrys.com | N38: Baru | P38: Distributor buah tropis cakupan nasional | Q38: https://blissberrys.com/
A39: B037 | B39: Tamimi Markets | C39: Timur Tengah | D39: Saudi Arabia | E39: Al Khobar | F39: Retail/Supermarket | G39: C | H39: Supermarket premium, impor langsung | I39: https://shop.tamimimarkets.com | N39: Baru | P39: Ritel premium & importir langsung | Q39: https://www.cbinsights.com/company/tamimi-markets
A40: B038 | B40: Al Shahabi Trading Co. | C40: Timur Tengah | D40: Qatar | E40: Doha | F40: Importir | G40: B | H40: Importir buah & sayur, salah satu tertua di Qatar | I40: https://alshahabifruits.com | N40: Baru | P40: Importir mapan di Qatar | Q40: https://alshahabifruits.com/
...

Sheet Penawaran
A1: CATATAN PENAWARAN HARGA
A2: No. Penawaran | B2: Tanggal | C2: ID Buyer | D2: Perusahaan | E2: Negara | F2: Incoterm | G2: Pelabuhan/Bandara Tujuan | H2: Grade | I2: Volume (kg) | J2: Harga (USD/kg) | K2: Nilai (USD) | L2: Nilai (IDR) | M2: Berlaku s/d | N2: Status | O2: Catatan
A3: QT-2026-001 | B3: 46296 | C3: B015 | D3: =IF(C3="","",IFERROR(INDEX('Database Buyer'!$B$3:$B$247,MATCH(C3,'Database Buyer'!$A$3:$A$247,0)),"ID tidak ditemukan")) | E3: =IF(C3="","",IFERROR(INDEX('Database Buyer'!$D$3:$D$247,MATCH(C3,'Database Buyer'!$A$3:$A$247,0)),"")) | F3: CIF | G3: Hong Kong (HKG) | H3: Super | I3: 1000 | J3: 3.5 | K3: =IF(OR(I3="",J3=""),"",I3*J3) | L3: =IF(K3="","",K3*Panduan!$C$22) | M3: 46310 | N3: Terkirim | O3: CONTOH: ganti/hapus baris ini. Harga ilustrasi, bukan harga pasar.
D4: =IF(C4="","",IFERROR(INDEX('Database Buyer'!$B$3:$B$247,MATCH(C4,'Database Buyer'!$A$3:$A$247,0)),"ID tidak ditemukan")) | E4: =IF(C4="","",IFERROR(INDEX('Database Buyer'!$D$3:$D$247,MATCH(C4,'Database Buyer'!$A$3:$A$247,0)),"")) | K4: =IF(OR(I4="",J4=""),"",I4*J4) | L4: =IF(K4="","",K4*Panduan!$C$22)
D5: =IF(C5="","",IFERROR(INDEX('Database Buyer'!$B$3:$B$247,MATCH(C5,'Database Buyer'!$A$3:$A$247,0)),"ID tidak ditemukan")) | E5: =IF(C5="","",IFERROR(INDEX('Database Buyer'!$D$3:$D$247,MATCH(C5,'Database Buyer'!$A$3:$A$247,0)),"")) | K5: =IF(OR(I5="",J5=""),"",I5*J5) | L5: =IF(K5="","",K5*Panduan!$C$22)
D6: =IF(C6="","",IFERROR(INDEX('Database Buyer'!$B$3:$B$247,MATCH(C6,'Database Buyer'!$A$3:$A$247,0)),"ID tidak ditemukan")) | E6: =IF(C6="","",IFERROR(INDEX('Database Buyer'!$D$3:$D$247,MATCH(C6,'Database Buyer'!$A$3:$A$247,0)),"")) | K6: =IF(OR(I6="",J6=""),"",I6*J6) | L6: =IF(K6="","",K6*Panduan!$C$22)
D7: =IF(C7="","",IFERROR(INDEX('Database Buyer'!$B$3:$B$247,MATCH(C7,'Database Buyer'!$A$3:$A$247,0)),"ID tidak ditemukan")) | E7: =IF(C7="","",IFERROR(INDEX('Database Buyer'!$D$3:$D$247,MATCH(C7,'Database Buyer'!$A$3:$A$247,0)),"")) | K7: =IF(OR(I7="",J7=""),"",I7*J7) | L7: =IF(K7="","",K7*Panduan!$C$22)
D8: =IF(C8="","",IFERROR(INDEX('Database Buyer'!$B$3:$B$247,MATCH(C8,'Database Buyer'!$A$3:$A$247,0)),"ID tidak ditemukan")) | E8: =IF(C8="","",IFERROR(INDEX('Database Buyer'!$D$3:$D$247,MATCH(C8,'Database Buyer'!$A$3:$A$247,0)),"")) | K8: =IF(OR(I8="",J8=""),"",I8*J8) | L8: =IF(K8="","",K8*Panduan!$C$22)
D9: =IF(C9="","",IFERROR(INDEX('Database Buyer'!$B$3:$B$247,MATCH(C9,'Database Buyer'!$A$3:$A$247,0)),"ID tidak ditemukan")) | E9: =IF(C9="","",IFERROR(INDEX('Database Buyer'!$D$3:$D$247,MATCH(C9,'Database Buyer'!$A$3:$A$247,0)),"")) | K9: =IF(OR(I9="",J9=""),"",I9*J9) | L9: =IF(K9="","",K9*Panduan!$C$22)
D10: =IF(C10="","",IFERROR(INDEX('Database Buyer'!$B$3:$B$247,MATCH(C10,'Database Buyer'!$A$3:$A$247,0)),"ID tidak ditemukan")) | E10: =IF(C10="","",IFERROR(INDEX('Database Buyer'!$D$3:$D$247,MATCH(C10,'Database Buyer'!$A$3:$A$247,0)),"")) | K10: =IF(OR(I10="",J10=""),"",I10*J10) | L10: =IF(K10="","",K10*Panduan!$C$22)
D11: =IF(C11="","",IFERROR(INDEX('Database Buyer'!$B$3:$B$247,MATCH(C11,'Database Buyer'!$A$3:$A$247,0)),"ID tidak ditemukan")) | E11: =IF(C11="","",IFERROR(INDEX('Database Buyer'!$D$3:$D$247,MATCH(C11,'Database Buyer'!$A$3:$A$247,0)),"")) | K11: =IF(OR(I11="",J11=""),"",I11*J11) | L11: =IF(K11="","",K11*Panduan!$C$22)
D12: =IF(C12="","",IFERROR(INDEX('Database Buyer'!$B$3:$B$247,MATCH(C12,'Database Buyer'!$A$3:$A$247,0)),"ID tidak ditemukan")) | E12: =IF(C12="","",IFERROR(INDEX('Database Buyer'!$D$3:$D$247,MATCH(C12,'Database Buyer'!$A$3:$A$247,0)),"")) | K12: =IF(OR(I12="",J12=""),"",I12*J12) | L12: =IF(K12="","",K12*Panduan!$C$22)
D13: =IF(C13="","",IFERROR(INDEX('Database Buyer'!$B$3:$B$247,MATCH(C13,'Database Buyer'!$A$3:$A$247,0)),"ID tidak ditemukan")) | E13: =IF(C13="","",IFERROR(INDEX('Database Buyer'!$D$3:$D$247,MATCH(C13,'Database Buyer'!$A$3:$A$247,0)),"")) | K13: =IF(OR(I13="",J13=""),"",I13*J13) | L13: =IF(K13="","",K13*Panduan!$C$22)
D14: =IF(C14="","",IFERROR(INDEX('Database Buyer'!$B$3:$B$247,MATCH(C14,'Database Buyer'!$A$3:$A$247,0)),"ID tidak ditemukan")) | E14: =IF(C14="","",IFERROR(INDEX('Database Buyer'!$D$3:$D$247,MATCH(C14,'Database Buyer'!$A$3:$A$247,0)),"")) | K14: =IF(OR(I14="",J14=""),"",I14*J14) | L14: =IF(K14="","",K14*Panduan!$C$22)
D15: =IF(C15="","",IFERROR(INDEX('Database Buyer'!$B$3:$B$247,MATCH(C15,'Database Buyer'!$A$3:$A$247,0)),"ID tidak ditemukan")) | E15: =IF(C15="","",IFERROR(INDEX('Database Buyer'!$D$3:$D$247,MATCH(C15,'Database Buyer'!$A$3:$A$247,0)),"")) | K15: =IF(OR(I15="",J15=""),"",I15*J15) | L15: =IF(K15="","",K15*Panduan!$C$22)
... D202: =IF(C202="","",IFERROR(INDEX('Database Buyer'!$B$3:$B$247,MATCH(C202,'Database Buyer'!$A$3:$A$247,0)),"ID tidak ditemukan")) | E202: =IF(C202="","",IFERROR(INDEX('Database Buyer'!$D$3:$D$247,MATCH(C202,'Database Buyer'!$A$3:$A$247,0)),"")) | K202: =IF(OR(I202="",J202=""),"",I202*J202) | L202: =IF(K202="","",K202*Panduan!$C$22)

Sheet Ringkasan
B2: RINGKASAN
B4: Negara | C4: Jml Buyer | D4: Prior. A | E4: Prior. B | F4: Prior. C | G4: Sudah Kontak | H4: Deal | I4: Penawaran (USD) | J4: Diterima (USD)
B5: China | C5: =COUNTIF('Database Buyer'!$D$3:$D$247,B5) | D5: =COUNTIFS('Database Buyer'!$D$3:$D$247,$B5,'Database Buyer'!$G$3:$G$247,"A") | E5: =COUNTIFS('Database Buyer'!$D$3:$D$247,$B5,'Database Buyer'!$G$3:$G$247,"B") | F5: =COUNTIFS('Database Buyer'!$D$3:$D$247,$B5,'Database Buyer'!$G$3:$G$247,"C") | G5: =C5-COUNTIFS('Database Buyer'!$D$3:$D$247,$B5,'Database Buyer'!$N$3:$N$247,"Baru") | H5: =COUNTIFS('Database Buyer'!$D$3:$D$247,$B5,'Database Buyer'!$N$3:$N$247,"Deal") | I5: =SUMIFS(Penawaran!$K$3:$K$202,Penawaran!$E$3:$E$202,$B5) | J5: =SUMIFS(Penawaran!$K$3:$K$202,Penawaran!$E$3:$E$202,$B5,Penawaran!$N$3:$N$202,"Diterima")
B6: Hong Kong | C6: =COUNTIF('Database Buyer'!$D$3:$D$247,B6) | D6: =COUNTIFS('Database Buyer'!$D$3:$D$247,$B6,'Database Buyer'!$G$3:$G$247,"A") | E6: =COUNTIFS('Database Buyer'!$D$3:$D$247,$B6,'Database Buyer'!$G$3:$G$247,"B") | F6: =COUNTIFS('Database Buyer'!$D$3:$D$247,$B6,'Database Buyer'!$G$3:$G$247,"C") | G6: =C6-COUNTIFS('Database Buyer'!$D$3:$D$247,$B6,'Database Buyer'!$N$3:$N$247,"Baru") | H6: =COUNTIFS('Database Buyer'!$D$3:$D$247,$B6,'Database Buyer'!$N$3:$N$247,"Deal") | I6: =SUMIFS(Penawaran!$K$3:$K$202,Penawaran!$E$3:$E$202,$B6) | J6: =SUMIFS(Penawaran!$K$3:$K$202,Penawaran!$E$3:$E$202,$B6,Penawaran!$N$3:$N$202,"Diterima")
B7: UAE | C7: =COUNTIF('Database Buyer'!$D$3:$D$247,B7) | D7: =COUNTIFS('Database Buyer'!$D$3:$D$247,$B7,'Database Buyer'!$G$3:$G$247,"A") | E7: =COUNTIFS('Database Buyer'!$D$3:$D$247,$B7,'Database Buyer'!$G$3:$G$247,"B") | F7: =COUNTIFS('Database Buyer'!$D$3:$D$247,$B7,'Database Buyer'!$G$3:$G$247,"C") | G7: =C7-COUNTIFS('Database Buyer'!$D$3:$D$247,$B7,'Database Buyer'!$N$3:$N$247,"Baru") | H7: =COUNTIFS('Database Buyer'!$D$3:$D$247,$B7,'Database Buyer'!$N$3:$N$247,"Deal") | I7: =SUMIFS(Penawaran!$K$3:$K$202,Penawaran!$E$3:$E$202,$B7) | J7: =SUMIFS(Penawaran!$K$3:$K$202,Penawaran!$E$3:$E$202,$B7,Penawaran!$N$3:$N$202,"Diterima")
B8: Saudi Arabia | C8: =COUNTIF('Database Buyer'!$D$3:$D$247,B8) | D8: =COUNTIFS('Database Buyer'!$D$3:$D$247,$B8,'Database Buyer'!$G$3:$G$247,"A") | E8: =COUNTIFS('Database Buyer'!$D$3:$D$247,$B8,'Database Buyer'!$G$3:$G$247,"B") | F8: =COUNTIFS('Database Buyer'!$D$3:$D$247,$B8,'Database Buyer'!$G$3:$G$247,"C") | G8: =C8-COUNTIFS('Database Buyer'!$D$3:$D$247,$B8,'Database Buyer'!$N$3:$N$247,"Baru") | H8: =COUNTIFS('Database Buyer'!$D$3:$D$247,$B8,'Database Buyer'!$N$3:$N$247,"Deal") | I8: =SUMIFS(Penawaran!$K$3:$K$202,Penawaran!$E$3:$E$202,$B8) | J8: =SUMIFS(Penawaran!$K$3:$K$202,Penawaran!$E$3:$E$202,$B8,Penawaran!$N$3:$N$202,"Diterima")
B9: Qatar | C9: =COUNTIF('Database Buyer'!$D$3:$D$247,B9) | D9: =COUNTIFS('Database Buyer'!$D$3:$D$247,$B9,'Database Buyer'!$G$3:$G$247,"A") | E9: =COUNTIFS('Database Buyer'!$D$3:$D$247,$B9,'Database Buyer'!$G$3:$G$247,"B") | F9: =COUNTIFS('Database Buyer'!$D$3:$D$247,$B9,'Database Buyer'!$G$3:$G$247,"C") | G9: =C9-COUNTIFS('Database Buyer'!$D$3:$D$247,$B9,'Database Buyer'!$N$3:$N$247,"Baru") | H9: =COUNTIFS('Database Buyer'!$D$3:$D$247,$B9,'Database Buyer'!$N$3:$N$247,"Deal") | I9: =SUMIFS(Penawaran!$K$3:$K$202,Penawaran!$E$3:$E$202,$B9) | J9: =SUMIFS(Penawaran!$K$3:$K$202,Penawaran!$E$3:$E$202,$B9,Penawaran!$N$3:$N$202,"Diterima")
B10: Kuwait | C10: =COUNTIF('Database Buyer'!$D$3:$D$247,B10) | D10: =COUNTIFS('Database Buyer'!$D$3:$D$247,$B10,'Database Buyer'!$G$3:$G$247,"A") | E10: =COUNTIFS('Database Buyer'!$D$3:$D$247,$B10,'Database Buyer'!$G$3:$G$247,"B") | F10: =COUNTIFS('Database Buyer'!$D$3:$D$247,$B10,'Database Buyer'!$G$3:$G$247,"C") | G10: =C10-COUNTIFS('Database Buyer'!$D$3:$D$247,$B10,'Database Buyer'!$N$3:$N$247,"Baru") | H10: =COUNTIFS('Database Buyer'!$D$3:$D$247,$B10,'Database Buyer'!$N$3:$N$247,"Deal") | I10: =SUMIFS(Penawaran!$K$3:$K$202,Penawaran!$E$3:$E$202,$B10) | J10: =SUMIFS(Penawaran!$K$3:$K$202,Penawaran!$E$3:$E$202,$B10,Penawaran!$N$3:$N$202,"Diterima")
B11: Oman | C11: =COUNTIF('Database Buyer'!$D$3:$D$247,B11) | D11: =COUNTIFS('Database Buyer'!$D$3:$D$247,$B11,'Database Buyer'!$G$3:$G$247,"A") | E11: =COUNTIFS('Database Buyer'!$D$3:$D$247,$B11,'Database Buyer'!$G$3:$G$247,"B") | F11: =COUNTIFS('Database Buyer'!$D$3:$D$247,$B11,'Database Buyer'!$G$3:$G$247,"C") | G11: =C11-COUNTIFS('Database Buyer'!$D$3:$D$247,$B11,'Database Buyer'!$N$3:$N$247,"Baru") | H11: =COUNTIFS('Database Buyer'!$D$3:$D$247,$B11,'Database Buyer'!$N$3:$N$247,"Deal") | I11: =SUMIFS(Penawaran!$K$3:$K$202,Penawaran!$E$3:$E$202,$B11) | J11: =SUMIFS(Penawaran!$K$3:$K$202,Penawaran!$E$3:$E$202,$B11,Penawaran!$N$3:$N$202,"Diterima")
B12: Bahrain | C12: =COUNTIF('Database Buyer'!$D$3:$D$247,B12) | D12: =COUNTIFS('Database Buyer'!$D$3:$D$247,$B12,'Database Buyer'!$G$3:$G$247,"A") | E12: =COUNTIFS('Database Buyer'!$D$3:$D$247,$B12,'Database Buyer'!$G$3:$G$247,"B") | F12: =COUNTIFS('Database Buyer'!$D$3:$D$247,$B12,'Database Buyer'!$G$3:$G$247,"C") | G12: =C12-COUNTIFS('Database Buyer'!$D$3:$D$247,$B12,'Database Buyer'!$N$3:$N$247,"Baru") | H12: =COUNTIFS('Database Buyer'!$D$3:$D$247,$B12,'Database Buyer'!$N$3:$N$247,"Deal") | I12: =SUMIFS(Penawaran!$K$3:$K$202,Penawaran!$E$3:$E$202,$B12) | J12: =SUMIFS(Penawaran!$K$3:$K$202,Penawaran!$E$3:$E$202,$B12,Penawaran!$N$3:$N$202,"Diterima")
B13: TOTAL | C13: =SUM(C5:C12) | D13: =SUM(D5:D12) | E13: =SUM(E5:E12) | F13: =SUM(F5:F12) | G13: =SUM(G5:G12) | H13: =SUM(H5:H12) | I13: =SUM(I5:I12) | J13: =SUM(J5:J12)
B15: Semua angka di sheet ini dihitung otomatis dari 'Database Buyer' dan 'Penawaran'.

Sheet Syarat Ekspor
A1: CHECKLIST SYARAT EKSPOR MANGGIS SEGAR
A3: Pasar | B3: Persyaratan | C3: Siap? ✓ | D3: Sumber
A4: China | B4: Protokol manggis RI–China (ditandatangani 11 Des 2017; ekspor perdana 18 Jan 2018) | D4: https://pertanian.go.id/?act=view&id=2513&show=news
A5: China | B5: Kebun terdaftar di Barantin & tercantum di daftar GACC; terapkan SOP, GAP, IPM | D5: https://www.tridge.com/market-guides/ID-mangosteen
A6: China | B6: Packing house teregistrasi (OKKPD/Bapanas + Barantin) dan disetujui GACC; berlaku 5 tahun | D6: https://badanpangan.go.id/blog/post/dorong-percepatan-persetujuan-protokol-ekspor-buah-di-tiongkok-nfa-lakukan-bilateral-meeting-dengan-gacc
A7: China | B7: Siap audit GACC (termasuk audit virtual kebun & packing house) | D7: https://dpkp.jogjaprov.go.id/
A8: China | B8: Phytosanitary Certificate Barantin tiap kiriman; sampling ≥2%; bebas lalat buah, kutu putih, kutu sisik, semut, tungau, tanah; batas residu pestisida | D8: https://www.tridge.com/market-guides/ID-mangosteen
A9: Hong Kong | B9: Pintu masuk utama: Pasar Buah Yau Ma Tei (±80% buah HK); banyak re-ekspor ke China | D9: https://en.wikipedia.org/wiki/Yau_Ma_Tei_Fruit_Market
A10: UAE | B10: Importir wajib punya izin impor MOCCAE sebelum kapal berangkat; data harus sama dengan Phytosanitary Certificate | D10: https://www.moccae.gov.ae/en/services/import-permit
A11: UAE | B11: Bebas OPT karantina & residu pestisida sesuai batas UAE | D11: https://site.moccae.gov.ae/en/services/export-import-services/release-of-agricultural-products-consignment.aspx
A12: Saudi Arabia | B12: Importir: akun SFDA + registrasi produk + lisensi impor MEWA. Eksportir buah segar saat ini tidak wajib registrasi SFDA | D12: https://www.sfda.gov.sa/sites/default/files/2021-08/GuideFreshFruitVegetableRegistrationLicensing.pdf
A13: Saudi Arabia | B13: Dokumen: Phytosanitary Certificate, Invoice, Certificate of Origin, Packing List; standar SFDA.FD/GSO 123 | D13: https://www.intertek.com/siteassets/gts/saudi-arabia/sfa-eig-sfda-exporter-and-importer-guidelines-r09.pdf
A14: GCC (umum) | B14: Sertifikat halal TIDAK wajib untuk buah segar, kecuali dilabeli 'Halal' | D14: https://halalfoundation.org/halal-certification-for-export-to-uae-saudi-arabia-and-gcc-mena-countries/
A15: Logistik | B15: Kemasan keranjang 7–7,5 kg, suhu ±7°C, daya simpan ±20 hari | D15: https://www.owafresh.com/trusted-mangosteen-distributor-from-indonesia-for-export/
... A17: Pasar | B17: Impor GCC naik 6–8 minggu sebelum Ramadan | D17: https://gulfbusiness.com/en/2026/logistics/dp-world-shows-ramadan-driven-spike-in-imports/
